Workbook

Sheet LEIA-ME
A1: Benchmark Fase 3: RAG jurídico × concorrentes
A3: Objetivo: medir se Jus IA, Jurídico AI, LLM genérico já respondem bem às 25 perguntas de balcão (Registro de Imóveis × LAI × LGPD). O resultado alimenta o Gate 1.
A4: 1. Aba Perguntas: o oficial/DPO preenche o gabarito (colunas amarelas) ANTES de avaliar.
A5: 2. Aba Respostas: uma linha por pergunta × ferramenta. Cole a resposta integral, sem editar.
A6: 3. Mesma redação, sessão nova, sem contexto extra em cada ferramenta.
A7: 4. As linhas 'RAG atual' e 'RAG Fase 3' são preenchidas pelo script run_rag_benchmark.py (--xlsx).
A8: 5. Dê a nota de 0 a 2 em cada critério comparando com o gabarito. A Nota (0-10) só aparece com os 5 critérios preenchidos.
A9: 6. Aba Parametros: preencha a assinatura mensal dos concorrentes e confira preço/câmbio.
A10: 7. A aba Resumo e o sinal do Gate 1 são calculados sozinhos.
A12: Legenda
A13: Preencher | B13: Célula de entrada (texto azul, fundo amarelo)
A14: Fórmula | B14: Calculado; não editar
A16: Rubrica (0 a 2 por critério)
A17: Critério | B17: 0 | C17: 1 | D17: 2
A18: Veredito | B18: errado | C18: ambíguo | D18: correto
A19: Fundamentação | B19: sem citação | C19: lei genérica | D19: dispositivo específico correto
A20: Norma CE | B20: ignora | C20: menciona | D20: aplica corretamente
A21: Acionável | B21: só teoria | C21: orientação | D21: ato/minuta utilizável
A22: Sem alucinação | B22: inventa norma | C22: impreciso | D22: nenhuma
A24: Exemplo de linha preenchida (formato esperado)
A25: ID / Ferramenta | B25: 6 / Jus IA
A26: Data da coleta | B26: 2026-09-25
A27: Versão / plano | B27: Plano Profissional (set/2026)
A28: Resposta integral | B28: Não. A informação sobre titularidade é fornecida por certidão...
A29: Fontes citadas | B29: Lei 6.015/73, art. 16-17; LGPD art. 7º
A30: Latência (s) | B30: 9
A31: Notas 0-2 | B31: Veredito 2 · Fundamentação 1 · Norma CE 0 · Acionável 1 · Alucinação 2 → Nota 6
A32: Observações | B32: Não citou o Código de Normas do CE nem gerou minuta.

Sheet Perguntas
A1: ID | B1: Categoria | C1: Pergunta | D1: Veredito esperado | E1: Base legal do gabarito | F1: Validado por | G1: Data da validação
A2: 1 | B2: Certidão | C2: Um terceiro sem vínculo pede certidão de inteiro teor de uma matrícula. Posso emitir sem exigir motivo?
A3: 2 | B3: Certidão | C3: A certidão de inteiro teor deve exibir o CPF completo dos proprietários?
A4: 3 | B4: Certidão | C4: Pedido de certidão da matrícula com o histórico de todos os ônus, incluindo penhoras já canceladas. Emito integralmente?
A5: 4 | B5: Busca | C5: Alguém pede para buscar "todos os imóveis em nome de fulano" informando só o nome. Posso fazer a busca e informar?
A6: 5 | B6: Busca | C6: Busca por CPF solicitada por um credor para localizar bens do devedor. Qual é o procedimento?
A7: 6 | B7: Informação verbal | C7: Um requerente pede, por telefone, o nome do proprietário de um imóvel. Posso informar?
A8: 7 | B8: Informação verbal | C8: Um vizinho pergunta se o imóvel ao lado tem hipoteca. Posso responder no balcão?
A9: 8 | B9: Poder público | C9: Uma prefeitura solicita lista de imóveis com proprietários e CPFs para cobrança de IPTU. Forneço? Em que formato?
A10: 9 | B10: Poder público | C10: A polícia pede por ofício dados de um proprietário sem ordem judicial. Como proceder?
A11: 10 | B11: Poder público | C11: O Ministério Público requisita certidões em massa. Há limite ou exigência de fundamentação?
A12: 11 | B12: Transparência | C12: O CPF do proprietário pode aparecer em dados publicados em portal de transparência ou em resposta a pedido via LAI?
A13: 12 | B13: Transparência | C13: Pedido via LAI sobre os emolumentos arrecadados pela serventia. É dever responder?
... A26: 25 | B26: Incidente | C26: Uma certidão com dados pessoais foi enviada ao e-mail errado. Quais são as obrigações da serventia?

Sheet Respostas
A1: ID | B1: Ferramenta | C1: Categoria | D1: Pergunta | E1: Data da coleta | F1: Versão / plano | G1: Resposta integral | H1: Fontes citadas | I1: Latência (s) | J1: Tokens entrada | K1: Tokens saída | L1: Custo estimado (R$) | M1: Veredito (0-2) | N1: Fundamentação (0-2) | O1: Norma CE (0-2) | P1: Acionável (0-2) | Q1: Sem alucinação (0-2) | R1: Nota (0-10) | S1: Observações | T1: Citações (total) | U1: Citações verificadas | V1: Taxa verificável | W1: Citações não verificadas | X1: Status da resposta
A2: 1 | B2: Jus IA | C2: =INDEX(Perguntas!$B$2:$B$26,MATCH(A2,Perguntas!$A$2:$A$26,0)) | D2: =INDEX(Perguntas!$C$2:$C$26,MATCH(A2,Perguntas!$A$2:$A$26,0)) | L2: =IF(COUNT(J2:K2)=2,(J2*Parametros!$B$3+K2*Parametros!$B$4)/1000000*Parametros!$B$5,"") | R2: =IF(COUNT(M2:Q2)=5,SUM(M2:Q2),"") | V2: =IF(AND(ISNUMBER(T2),T2>0),U2/T2,"")
A3: 2 | B3: Jus IA | C3: =INDEX(Perguntas!$B$2:$B$26,MATCH(A3,Perguntas!$A$2:$A$26,0)) | D3: =INDEX(Perguntas!$C$2:$C$26,MATCH(A3,Perguntas!$A$2:$A$26,0)) | L3: =IF(COUNT(J3:K3)=2,(J3*Parametros!$B$3+K3*Parametros!$B$4)/1000000*Parametros!$B$5,"") | R3: =IF(COUNT(M3:Q3)=5,SUM(M3:Q3),"") | V3: =IF(AND(ISNUMBER(T3),T3>0),U3/T3,"")
A4: 3 | B4: Jus IA | C4: =INDEX(Perguntas!$B$2:$B$26,MATCH(A4,Perguntas!$A$2:$A$26,0)) | D4: =INDEX(Perguntas!$C$2:$C$26,MATCH(A4,Perguntas!$A$2:$A$26,0)) | L4: =IF(COUNT(J4:K4)=2,(J4*Parametros!$B$3+K4*Parametros!$B$4)/1000000*Parametros!$B$5,"") | R4: =IF(COUNT(M4:Q4)=5,SUM(M4:Q4),"") | V4: =IF(AND(ISNUMBER(T4),T4>0),U4/T4,"")
A5: 4 | B5: Jus IA | C5: =INDEX(Perguntas!$B$2:$B$26,MATCH(A5,Perguntas!$A$2:$A$26,0)) | D5: =INDEX(Perguntas!$C$2:$C$26,MATCH(A5,Perguntas!$A$2:$A$26,0)) | L5: =IF(COUNT(J5:K5)=2,(J5*Parametros!$B$3+K5*Parametros!$B$4)/1000000*Parametros!$B$5,"") | R5: =IF(COUNT(M5:Q5)=5,SUM(M5:Q5),"") | V5: =IF(AND(ISNUMBER(T5),T5>0),U5/T5,"")
A6: 5 | B6: Jus IA | C6: =INDEX(Perguntas!$B$2:$B$26,MATCH(A6,Perguntas!$A$2:$A$26,0)) | D6: =INDEX(Perguntas!$C$2:$C$26,MATCH(A6,Perguntas!$A$2:$A$26,0)) | L6: =IF(COUNT(J6:K6)=2,(J6*Parametros!$B$3+K6*Parametros!$B$4)/1000000*Parametros!$B$5,"") | R6: =IF(COUNT(M6:Q6)=5,SUM(M6:Q6),"") | V6: =IF(AND(ISNUMBER(T6),T6>0),U6/T6,"")
A7: 6 | B7: Jus IA | C7: =INDEX(Perguntas!$B$2:$B$26,MATCH(A7,Perguntas!$A$2:$A$26,0)) | D7: =INDEX(Perguntas!$C$2:$C$26,MATCH(A7,Perguntas!$A$2:$A$26,0)) | L7: =IF(COUNT(J7:K7)=2,(J7*Parametros!$B$3+K7*Parametros!$B$4)/1000000*Parametros!$B$5,"") | R7: =IF(COUNT(M7:Q7)=5,SUM(M7:Q7),"") | V7: =IF(AND(ISNUMBER(T7),T7>0),U7/T7,"")
A8: 7 | B8: Jus IA | C8: =INDEX(Perguntas!$B$2:$B$26,MATCH(A8,Perguntas!$A$2:$A$26,0)) | D8: =INDEX(Perguntas!$C$2:$C$26,MATCH(A8,Perguntas!$A$2:$A$26,0)) | L8: =IF(COUNT(J8:K8)=2,(J8*Parametros!$B$3+K8*Parametros!$B$4)/1000000*Parametros!$B$5,"") | R8: =IF(COUNT(M8:Q8)=5,SUM(M8:Q8),"") | V8: =IF(AND(ISNUMBER(T8),T8>0),U8/T8,"")
A9: 8 | B9: Jus IA | C9: =INDEX(Perguntas!$B$2:$B$26,MATCH(A9,Perguntas!$A$2:$A$26,0)) | D9: =INDEX(Perguntas!$C$2:$C$26,MATCH(A9,Perguntas!$A$2:$A$26,0)) | L9: =IF(COUNT(J9:K9)=2,(J9*Parametros!$B$3+K9*Parametros!$B$4)/1000000*Parametros!$B$5,"") | R9: =IF(COUNT(M9:Q9)=5,SUM(M9:Q9),"") | V9: =IF(AND(ISNUMBER(T9),T9>0),U9/T9,"")
A10: 9 | B10: Jus IA | C10: =INDEX(Perguntas!$B$2:$B$26,MATCH(A10,Perguntas!$A$2:$A$26,0)) | D10: =INDEX(Perguntas!$C$2:$C$26,MATCH(A10,Perguntas!$A$2:$A$26,0)) | L10: =IF(COUNT(J10:K10)=2,(J10*Parametros!$B$3+K10*Parametros!$B$4)/1000000*Parametros!$B$5,"") | R10: =IF(COUNT(M10:Q10)=5,SUM(M10:Q10),"") | V10: =IF(AND(ISNUMBER(T10),T10>0),U10/T10,"")
A11: 10 | B11: Jus IA | C11: =INDEX(Perguntas!$B$2:$B$26,MATCH(A11,Perguntas!$A$2:$A$26,0)) | D11: =INDEX(Perguntas!$C$2:$C$26,MATCH(A11,Perguntas!$A$2:$A$26,0)) | L11: =IF(COUNT(J11:K11)=2,(J11*Parametros!$B$3+K11*Parametros!$B$4)/1000000*Parametros!$B$5,"") | R11: =IF(COUNT(M11:Q11)=5,SUM(M11:Q11),"") | V11: =IF(AND(ISNUMBER(T11),T11>0),U11/T11,"")
A12: 11 | B12: Jus IA | C12: =INDEX(Perguntas!$B$2:$B$26,MATCH(A12,Perguntas!$A$2:$A$26,0)) | D12: =INDEX(Perguntas!$C$2:$C$26,MATCH(A12,Perguntas!$A$2:$A$26,0)) | L12: =IF(COUNT(J12:K12)=2,(J12*Parametros!$B$3+K12*Parametros!$B$4)/1000000*Parametros!$B$5,"") | R12: =IF(COUNT(M12:Q12)=5,SUM(M12:Q12),"") | V12: =IF(AND(ISNUMBER(T12),T12>0),U12/T12,"")
A13: 12 | B13: Jus IA | C13: =INDEX(Perguntas!$B$2:$B$26,MATCH(A13,Perguntas!$A$2:$A$26,0)) | D13: =INDEX(Perguntas!$C$2:$C$26,MATCH(A13,Perguntas!$A$2:$A$26,0)) | L13: =IF(COUNT(J13:K13)=2,(J13*Parametros!$B$3+K13*Parametros!$B$4)/1000000*Parametros!$B$5,"") | R13: =IF(COUNT(M13:Q13)=5,SUM(M13:Q13),"") | V13: =IF(AND(ISNUMBER(T13),T13>0),U13/T13,"")
... A76: 25 | B76: LLM genérico | C76: =INDEX(Perguntas!$B$2:$B$26,MATCH(A76,Perguntas!$A$2:$A$26,0)) | D76: =INDEX(Perguntas!$C$2:$C$26,MATCH(A76,Perguntas!$A$2:$A$26,0)) | L76: =IF(COUNT(J76:K76)=2,(J76*Parametros!$B$3+K76*Parametros!$B$4)/1000000*Parametros!$B$5,"") | R76: =IF(COUNT(M76:Q76)=5,SUM(M76:Q76),"") | V76: =IF(AND(ISNUMBER(T76),T76>0),U76/T76,"")
A77: 1 | B77: RAG atual | C77: =INDEX(Perguntas!$B$2:$B$26,MATCH(A77,Perguntas!$A$2:$A$26,0)) | D77: =INDEX(Perguntas!$C$2:$C$26,MATCH(A77,Perguntas!$A$2:$A$26,0)) | E77: 2026-09-23 | F77: groq/openai/gpt-oss-120b k=5 (cdde83a) | G77: Não encontrado no corpus. | H77: manual_praticas_cartorarias_1_grau.pdf:p5; curso-159994-aula-10-aeca-completo.pdf:p13; Lei_licitacoes_contratos_administrativos_4ed.pdf:p13; curso-159994-aula-06-bonus-799b-completo.pdf:p23; curso-160250-aula-00-480f-completo.pdf:p4 | I77: 2.81 | J77: 1956 | K77: 122 | L77: =IF(COUNT(J77:K77)=2,(J77*Parametros!$B$3+K77*Parametros!$B$4)/1000000*Parametros!$B$5,"") | R77: =IF(COUNT(M77:Q77)=5,SUM(M77:Q77),"") | V77: =IF(AND(ISNUMBER(T77),T77>0),U77/T77,"") | X77: NAO_ENCONTRADO
A78: 2 | B78: RAG atual | C78: =INDEX(Perguntas!$B$2:$B$26,MATCH(A78,Perguntas!$A$2:$A$26,0)) | D78: =INDEX(Perguntas!$C$2:$C$26,MATCH(A78,Perguntas!$A$2:$A$26,0)) | E78: 2026-09-23 | F78: groq/openai/gpt-oss-20b k=5 (cdde83a) | G78: Não encontrado no corpus. | H78: curso-160250-aula-01-b2c9-completo.pdf:p115; Lei_licitacoes_contratos_administrativos_4ed.pdf:p51; curso-159994-aula-06-43dd-completo.pdf:p59; curso-159994-aula-02-daa4-completo.pdf:p84; Lei_licitacoes_contratos_administrativos_4ed.pdf:p23 | I78: 1.34 | J78: 2045 | K78: 231 | L78: =IF(COUNT(J78:K78)=2,(J78*Parametros!$B$3+K78*Parametros!$B$4)/1000000*Parametros!$B$5,"") | R78: =IF(COUNT(M78:Q78)=5,SUM(M78:Q78),"") | V78: =IF(AND(ISNUMBER(T78),T78>0),U78/T78,"") | X78: NAO_ENCONTRADO
A79: 3 | B79: RAG atual | C79: =INDEX(Perguntas!$B$2:$B$26,MATCH(A79,Perguntas!$A$2:$A$26,0)) | D79: =INDEX(Perguntas!$C$2:$C$26,MATCH(A79,Perguntas!$A$2:$A$26,0)) | E79: 2026-09-23 | F79: groq/openai/gpt-oss-120b k=5 (cdde83a) | G79: Não encontrado no corpus | H79: LGPD-2023-ANPD.pdf:p9; curso-159994-aula-02-daa4-completo.pdf:p65; Lei_licitacoes_contratos_administrativos_4ed.pdf:p75; curso-159994-aula-11-d0d4-completo.pdf:p51; curso-159994-aula-02-daa4-completo.pdf:p58 | I79: 1.22 | J79: 1971 | K79: 171 | L79: =IF(COUNT(J79:K79)=2,(J79*Parametros!$B$3+K79*Parametros!$B$4)/1000000*Parametros!$B$5,"") | R79: =IF(COUNT(M79:Q79)=5,SUM(M79:Q79),"") | V79: =IF(AND(ISNUMBER(T79),T79>0),U79/T79,"") | X79: NAO_ENCONTRADO
A80: 4 | B80: RAG atual | C80: =INDEX(Perguntas!$B$2:$B$26,MATCH(A80,Perguntas!$A$2:$A$26,0)) | D80: =INDEX(Perguntas!$C$2:$C$26,MATCH(A80,Perguntas!$A$2:$A$26,0)) | E80: 2026-09-23 | F80: groq/openai/gpt-oss-120b k=5 (cdde83a) | G80: Não encontrado no corpus. | H80: GTA_executivo_federal_7ed.pdf:p8; gta_executivo_federal_7ed.pdf:p8; cartilha_inss_digital_oabsp.pdf:p34; GTA_executivo_federal_7ed.pdf:p34; gta_executivo_federal_7ed.pdf:p34 | I80: 1.32 | J80: 1862 | K80: 148 | L80: =IF(COUNT(J80:K80)=2,(J80*Parametros!$B$3+K80*Parametros!$B$4)/1000000*Parametros!$B$5,"") | R80: =IF(COUNT(M80:Q80)=5,SUM(M80:Q80),"") | V80: =IF(AND(ISNUMBER(T80),T80>0),U80/T80,"") | X80: NAO_ENCONTRADO
A81: 5 | B81: RAG atual | C81: =INDEX(Perguntas!$B$2:$B$26,MATCH(A81,Perguntas!$A$2:$A$26,0)) | D81: =INDEX(Perguntas!$C$2:$C$26,MATCH(A81,Perguntas!$A$2:$A$26,0)) | E81: 2026-09-23 | F81: groq/openai/gpt-oss-20b k=5 (cdde83a) | G81: **Não encontrado no corpus** | H81: manual_praticas_cartorarias_1_grau.pdf:p27; GTA_executivo_federal_7ed.pdf:p28; gta_executivo_federal_7ed.pdf:p28; LGPD-2023-ANPD.pdf:p9; GTA_executivo_federal_7ed.pdf:p29 | I81: 1.66 | J81: 1882 | K81: 104 | L81: =IF(COUNT(J81:K81)=2,(J81*Parametros!$B$3+K81*Parametros!$B$4)/1000000*Parametros!$B$5,"") | R81: =IF(COUNT(M81:Q81)=5,SUM(M81:Q81),"") | V81: =IF(AND(ISNUMBER(T81),T81>0),U81/T81,"") | X81: NAO_ENCONTRADO
A82: 6 | B82: RAG atual | C82: =INDEX(Perguntas!$B$2:$B$26,MATCH(A82,Perguntas!$A$2:$A$26,0)) | D82: =INDEX(Perguntas!$C$2:$C$26,MATCH(A82,Perguntas!$A$2:$A$26,0)) | E82: 2026-09-23 | F82: groq/openai/gpt-oss-20b k=5 (cdde83a) | G82: Não encontrado no corpus. | H82: inss_beneficios.pdf:p1; cartilha_inss_digital_oabsp.pdf:p18; cartilha_inss_digital_oabsp.pdf:p42; GTA_executivo_federal_7ed.pdf:p40; gta_executivo_federal_7ed.pdf:p40 | I82: 8.21 | J82: 1592 | K82: 363 | L82: =IF(COUNT(J82:K82)=2,(J82*Parametros!$B$3+K82*Parametros!$B$4)/1000000*Parametros!$B$5,"") | R82: =IF(COUNT(M82:Q82)=5,SUM(M82:Q82),"") | V82: =IF(AND(ISNUMBER(T82),T82>0),U82/T82,"") | X82: NAO_ENCONTRADO
A83: 7 | B83: RAG atual | C83: =INDEX(Perguntas!$B$2:$B$26,MATCH(A83,Perguntas!$A$2:$A$26,0)) | D83: =INDEX(Perguntas!$C$2:$C$26,MATCH(A83,Perguntas!$A$2:$A$26,0)) | E83: 2026-09-23 | F83: groq/openai/gpt-oss-20b k=5 (cdde83a) | G83: Não encontrado no corpus. | H83: manual_praticas_cartorarias_1_grau.pdf:p40; curso-159994-aula-23-d320-completo.pdf:p8; curso-159994-aula-23-d320-completo.pdf:p36; curso-159994-aula-07-292a-completo.pdf:p102; curso-159994-aula-07-292a-completo.pdf:p76 | I83: 13.87 | J83: 1792 | K83: 163 | L83: =IF(COUNT(J83:K83)=2,(J83*Parametros!$B$3+K83*Parametros!$B$4)/1000000*Parametros!$B$5,"") | R83: =IF(COUNT(M83:Q83)=5,SUM(M83:Q83),"") | V83: =IF(AND(ISNUMBER(T83),T83>0),U83/T83,"") | X83: NAO_ENCONTRADO
A84: 8 | B84: RAG atual | C84: =INDEX(Perguntas!$B$2:$B$26,MATCH(A84,Perguntas!$A$2:$A$26,0)) | D84: =INDEX(Perguntas!$C$2:$C$26,MATCH(A84,Perguntas!$A$2:$A$26,0)) | E84: 2026-09-23 | F84: groq/openai/gpt-oss-120b k=5 (cdde83a) | G84: Não encontrado no corpus | H84: Lei_licitacoes_contratos_administrativos_4ed.pdf:p141; LGPD-2023-ANPD.pdf:p48; curso-159994-aula-24-bf9f-completo.pdf:p63; GTA_executivo_federal_7ed.pdf:p31; gta_executivo_federal_7ed.pdf:p31 | I84: 1.33 | J84: 1938 | K84: 242 | L84: =IF(COUNT(J84:K84)=2,(J84*Parametros!$B$3+K84*Parametros!$B$4)/1000000*Parametros!$B$5,"") | R84: =IF(COUNT(M84:Q84)=5,SUM(M84:Q84),"") | V84: =IF(AND(ISNUMBER(T84),T84>0),U84/T84,"") | X84: NAO_ENCONTRADO
A85: 9 | B85: RAG atual | C85: =INDEX(Perguntas!$B$2:$B$26,MATCH(A85,Perguntas!$A$2:$A$26,0)) | D85: =INDEX(Perguntas!$C$2:$C$26,MATCH(A85,Perguntas!$A$2:$A$26,0)) | E85: 2026-09-23 | F85: groq/openai/gpt-oss-20b k=5 (cdde83a) | G85: **Resposta** Para que a polícia possa obter dados de um proprietário por ofício, é necessário observar as disposições legais que regulam o acesso a dados pessoais e a atuação policial. **1. Princípio da Necessidade e da Finalidade** - **LGPD**: o tratamento de dados pessoais só pode ocorrer quando houver uma base legal (art. 5º). - **Polícia**: a coleta de dados deve estar vinculada a uma finalidade legítima, como investigação de infração de trânsito ou de crime. **2. Necessidade de Ordem Judicial ou Autorização Legal** - **CPC**: a citação e a obtenção de documentos de terceiros normalmente requerem **ordem judicial** (art. 225). - **CTB**: não há previsão específica que autorize a polícia a solicitar dados de proprietários sem ordem judicial; a lei exige que a informação seja obtida por meio de procedimento legalmente previsto. **3. Procedimento a Seguir** - **Rejeitar** o ofício se não houver ordem judicial ou base legal clara. - **Solicitar** à autoridade policial que apresente a **ordem judicial** ou outro documento que comprove a base legal (por exemplo, autorização de investigação criminal). - **Verificar** se existe alguma norma específica que autorize a polícia a acessar dados sem ordem judicial (ex.: Lei de Execução Penal, Lei de Segurança Pública). Se existir, seguir o procedimento previsto. **4. Caso a Ordem Judicial Não Esteja Disponível** - **Encaminhar** o pedido ao juiz competente para que seja emitida a ordem de acesso aos dados. - **Manter** o sigilo e a confidencialidade dos dados, conforme exigido pela LGPD. **Resumo em Lista** - **LGPD**: exigir base legal (consentimento, obrigação legal, etc.). - **CPC**: requer ordem judicial para obtenção de dados de terceiros. - **CTB**: não autoriza acesso sem ordem judicial. - **Procedimento**: rejeitar ofício sem ordem, solicitar ordem judicial ou verificar norma específica que autorize. --- Se houver alguma dúvida adicional sobre a base legal específica ou sobre a necessidade de autorização judicial, consulte o órgão jurídico competente. | H85: curso-159994-aula-04-b323-completo.pdf:p36; curso-159994-aula-04-b323-completo.pdf:p45; LGPD-2023-ANPD.pdf:p13; manual_praticas_cartorarias_1_grau.pdf:p32; curso-159994-aula-04-b323-completo.pdf:p35 | I85: 8.26 | J85: 1882 | K85: 905 | L85: =IF(COUNT(J85:K85)=2,(J85*Parametros!$B$3+K85*Parametros!$B$4)/1000000*Parametros!$B$5,"") | R85: =IF(COUNT(M85:Q85)=5,SUM(M85:Q85),"") | V85: =IF(AND(ISNUMBER(T85),T85>0),U85/T85,"") | X85: RESPONDIDA
A86: 10 | B86: RAG atual | C86: =INDEX(Perguntas!$B$2:$B$26,MATCH(A86,Perguntas!$A$2:$A$26,0)) | D86: =INDEX(Perguntas!$C$2:$C$26,MATCH(A86,Perguntas!$A$2:$A$26,0)) | E86: 2026-09-23 | F86: groq/openai/gpt-oss-20b k=5 (cdde83a) | G86: **Não encontrado no corpus** | H86: GTA_executivo_federal_7ed.pdf:p49; gta_executivo_federal_7ed.pdf:p49; curso-159994-aula-21-f255-completo.pdf:p10; LGPD-2023-ANPD.pdf:p25; Lei_licitacoes_contratos_administrativos_4ed.pdf:p78 | I86: 18.06 | J86: 1682 | K86: 97 | L86: =IF(COUNT(J86:K86)=2,(J86*Parametros!$B$3+K86*Parametros!$B$4)/1000000*Parametros!$B$5,"") | R86: =IF(COUNT(M86:Q86)=5,SUM(M86:Q86),"") | V86: =IF(AND(ISNUMBER(T86),T86>0),U86/T86,"") | X86: NAO_ENCONTRADO
A87: 11 | B87: RAG atual | C87: =INDEX(Perguntas!$B$2:$B$26,MATCH(A87,Perguntas!$A$2:$A$26,0)) | D87: =INDEX(Perguntas!$C$2:$C$26,MATCH(A87,Perguntas!$A$2:$A$26,0)) | E87: 2026-09-23 | F87: groq/openai/gpt-oss-120b k=5 (cdde83a) | G87: Não encontrado no corpus | H87: GTA_executivo_federal_7ed.pdf:p62; gta_executivo_federal_7ed.pdf:p62; GTA_executivo_federal_7ed.pdf:p52; gta_executivo_federal_7ed.pdf:p52; GTA_executivo_federal_7ed.pdf:p38 | I87: 1.49 | J87: 1789 | K87: 147 | L87: =IF(COUNT(J87:K87)=2,(J87*Parametros!$B$3+K87*Parametros!$B$4)/1000000*Parametros!$B$5,"") | R87: =IF(COUNT(M87:Q87)=5,SUM(M87:Q87),"") | V87: =IF(AND(ISNUMBER(T87),T87>0),U87/T87,"") | X87: NAO_ENCONTRADO
A88: 12 | B88: RAG atual | C88: =INDEX(Perguntas!$B$2:$B$26,MATCH(A88,Perguntas!$A$2:$A$26,0)) | D88: =INDEX(Perguntas!$C$2:$C$26,MATCH(A88,Perguntas!$A$2:$A$26,0)) | E88: 2026-09-23 | F88: groq/openai/gpt-oss-20b k=5 (cdde83a) | G88: Não encontrado no corpus | H88: GTA_executivo_federal_7ed.pdf:p17; gta_executivo_federal_7ed.pdf:p17; Lei_licitacoes_contratos_administrativos_4ed.pdf:p23; curso-159994-aula-06-43dd-completo.pdf:p56; inss_beneficios.pdf:p1 | I88: 7.22 | J88: 1560 | K88: 201 | L88: =IF(COUNT(J88:K88)=2,(J88*Parametros!$B$3+K88*Parametros!$B$4)/1000000*Parametros!$B$5,"") | R88: =IF(COUNT(M88:Q88)=5,SUM(M88:Q88),"") | V88: =IF(AND(ISNUMBER(T88),T88>0),U88/T88,"") | X88: NAO_ENCONTRADO
... A101: 25 | B101: RAG atual | C101: =INDEX(Perguntas!$B$2:$B$26,MATCH(A101,Perguntas!$A$2:$A$26,0)) | D101: =INDEX(Perguntas!$C$2:$C$26,MATCH(A101,Perguntas!$A$2:$A$26,0)) | E101: 2026-09-23 | F101: groq/openai/gpt-oss-20b k=5 (cdde83a) | G101: **Não encontrado no corpus** | H101: cartilha_inss_digital_oabsp.pdf:p18; GTA_executivo_federal_7ed.pdf:p41; gta_executivo_federal_7ed.pdf:p41; GTA_executivo_federal_7ed.pdf:p38; gta_executivo_federal_7ed.pdf:p38 | I101: 13.25 | J101: 1908 | K101: 113 | L101: =IF(COUNT(J101:K101)=2,(J101*Parametros!$B$3+K101*Parametros!$B$4)/1000000*Parametros!$B$5,"") | R101: =IF(COUNT(M101:Q101)=5,SUM(M101:Q101),"") | V101: =IF(AND(ISNUMBER(T101),T101>0),U101/T101,"") | X101: NAO_ENCONTRADO
A102: 1 | B102: RAG Fase 3 | C102: =INDEX(Perguntas!$B$2:$B$26,MATCH(A102,Perguntas!$A$2:$A$26,0)) | D102: =INDEX(Perguntas!$C$2:$C$26,MATCH(A102,Perguntas!$A$2:$A$26,0)) | E102: 2026-10-13 | F102: groq/openai/gpt-oss-120b k=5 (26168ce) | G102: **Resposta:** Sim. A certidão de inteiro teor pode ser emitida ao requerente, ainda que ele seja um terceiro sem vínculo ou sem apresentar justificativa para o pedido. **Fundamentação normativa** 1. **Lei nº 6.015/1973 – Art. 19, § 11** > “No âmbito do registro de imóveis, a certidão de inteiro teor da matrícula conterá a reprodução de todo seu conteúdo e será suficiente para fins de comprovação de propriedade, direitos, ônus reais e restrições sobre o imóvel, independentemente de certificação específica pelo oficial.” O dispositivo não impõe a exigência de motivação ou vínculo do requerente para a expedição da certidão. 2. **Código de Normas da CGJ‑CE – Art. 1.131, §§ 1‑2** > “Ao receber o pedido de certidão, o Oficial fornecerá, obrigatoriamente, ao requerente protocolo… e o prazo para a entrega do documento que não poderá exceder a 05 (cinco) dias úteis… A certidão será lavrada em inteiro teor… não podendo ser retardada por mais de 5 (cinco) dias úteis.” Não há previsão de necessidade de justificativa ou de vínculo do interessado; o oficial apenas cumpre o prazo e informa os custos. 3. **Provimento CNJ 149/2023 – Art. 327** > “A certidão de inteiro teor digital solicitada durante o horário de expediente… será emitida e disponibilizada dentro de no máximo 2 horas… e ficará disponível para download pelo requerente pelo prazo mínimo de 30 dias.” O provimento regula apenas o prazo e a forma de disponibilização, não condicionando a emissão a motivo ou vínculo. 4. **Provimento CNJ 149/2023 – Art. 200** (restrição que não se aplica ao caso) > “É vedada a expedição de nova certidão de inteiro teor… tendo como única fonte de consulta anterior certidão expedida por unidade do serviço extrajudicial.” Essa vedação refere‑se à origem da informação, não à identidade do requerente. **Conclusão prática** O ato registral deve ser praticado integralmente: a serventia pode expedir a certidão de inteiro teor da matrícula ao terceiro, sem necessidade de exigir motivo ou comprovar vínculo. O oficial observará apenas os requisitos de protocolo, pagamento de emolumentos e os prazos estabelecidos nos dispositivos citados. | H102: Lei 6.015/1973 — Art. 19:p0; Código de Normas CGJ-CE — Art. 1131:p229; Provimento CNJ 149/2023 — Art. 327:p209; Provimento CNJ 149/2023 — Art. 200:p94 | I102: 3 | J102: 1738 | K102: 816 | L102: =IF(COUNT(J102:K102)=2,(J102*Parametros!$B$3+K102*Parametros!$B$4)/1000000*Parametros!$B$5,"") | R102: =IF(COUNT(M102:Q102)=5,SUM(M102:Q102),"") | T102: 4 | U102: 4 | V102: =IF(AND(ISNUMBER(T102),T102>0),U102/T102,"") | X102: RESPONDIDA
A103: 2 | B103: RAG Fase 3 | C103: =INDEX(Perguntas!$B$2:$B$26,MATCH(A103,Perguntas!$A$2:$A$26,0)) | D103: =INDEX(Perguntas!$C$2:$C$26,MATCH(A103,Perguntas!$A$2:$A$26,0)) | E103: 2026-10-13 | F103: groq/openai/gpt-oss-20b k=5 (26168ce) | G103: Não encontrado no corpus. | H103: Código de Normas CGJ-CE — Art. 1502:p308; Código de Normas CGJ-CE — Art. 1131:p229; Lei 6.015/1973 — Art. 19:p0; Código de Normas CGJ-CE — Art. 1633:p333 | I103: 0.97 | J103: 1698 | K103: 224 | L103: =IF(COUNT(J103:K103)=2,(J103*Parametros!$B$3+K103*Parametros!$B$4)/1000000*Parametros!$B$5,"") | R103: =IF(COUNT(M103:Q103)=5,SUM(M103:Q103),"") | T103: 0 | U103: 0 | V103: =IF(AND(ISNUMBER(T103),T103>0),U103/T103,"") | X103: NAO_ENCONTRADO
A104: 3 | B104: RAG Fase 3 | C104: =INDEX(Perguntas!$B$2:$B$26,MATCH(A104,Perguntas!$A$2:$A$26,0)) | D104: =INDEX(Perguntas!$C$2:$C$26,MATCH(A104,Perguntas!$A$2:$A$26,0)) | E104: 2026-10-13 | F104: groq/openai/gpt-oss-120b k=5 (26168ce) | G104: **Decisão:** Indeferir o pedido via **Nota Devolutiva** – a certidão deverá conter apenas os ônus reais **não cancelados**, nos termos da normativa vigente. **Fundamentação normativa** 1. **Código de Normas da CGJ‑CE – Art. 1.129** > “As certidões dos imóveis que já forem objeto de matrícula eletrônica, após a ‘primeira qualificação eletrônica’, serão expedidas … contendo a situação jurídica atual do imóvel, ou seja, sua descrição, titularidade e os ônus reais **não cancelados**.” O dispositivo delimita expressamente o conteúdo da certidão à situação jurídica **atual**, excluindo, portanto, ônus que já tenham sido cancelados. 2. **Código de Normas da CGJ‑CE – Art. 1.682, parágrafo único** > “A expedição de certidão de atos anteriores da cadeia filiatória do imóvel depende de identificação segura do requerente e de indicação da finalidade.” Não há previsão de que a certidão de histórico completo (incluindo ônus cancelados) seja emitida de forma automática; sua expedição exigiria requisitos adicionais que não foram atendidos no pedido. **Conclusão operacional** - O pedido de certidão contendo **todo o histórico de ônus, inclusive penhoras já canceladas**, ultrapassa o escopo definido pelos artigos acima. - Assim, o ato registral **não deve ser praticado integralmente**. - O cartório deve **indeferir** o pedido mediante **Nota Devolutiva**, orientando o requerente a formular novo pedido específico, com identificação segura e indicação de finalidade, caso deseje acesso a atos anteriores da cadeia filiatória, nos termos do art. 1.682, § único. | H104: Lei 6.015/1973 — Art. 230:p0; Código de Normas CGJ-CE — Art. 1129:p229; Código de Normas CGJ-CE — Art. 1682:p345; Código de Normas CGJ-CE — Art. 1259:p256 | I104: 2.41 | J104: 1410 | K104: 876 | L104: =IF(COUNT(J104:K104)=2,(J104*Parametros!$B$3+K104*Parametros!$B$4)/1000000*Parametros!$B$5,"") | R104: =IF(COUNT(M104:Q104)=5,SUM(M104:Q104),"") | T104: 3 | U104: 3 | V104: =IF(AND(ISNUMBER(T104),T104>0),U104/T104,"") | X104: RESPONDIDA
A105: 4 | B105: RAG Fase 3 | C105: =INDEX(Perguntas!$B$2:$B$26,MATCH(A105,Perguntas!$A$2:$A$26,0)) | D105: =INDEX(Perguntas!$C$2:$C$26,MATCH(A105,Perguntas!$A$2:$A$26,0)) | E105: 2026-10-13 | F105: groq/openai/gpt-oss-120b k=5 (26168ce) | G105: **Resposta:** Indeferir o pedido via **Nota Devolutiva**. **Fundamentação normativa** - **Código de Normas CGJ‑CE – Art. 1.128, § 2º, inc. IV**: “as requisições de buscas fundadas exclusivamente no indicador pessoal ou real” são vedadas. O pedido “todos os imóveis em nome de fulano”, apresentado apenas com o nome (indicador pessoal), enquadra‑se exatamente nessa hipótese, não havendo a exigência de identificação do requerente nem de finalidade específica. - **Lei Geral de Proteção de Dados (LGPD) – Art. 7º** (não explicitado no corpus, mas aplicável por analogia): o tratamento de dados pessoais (lista de imóveis vinculados a pessoa física) só pode ocorrer mediante consentimento ou outra hipótese legal, o que não foi demonstrado no pedido. **Conclusão operacional** - O registro não deve ser praticado integralmente nem com tarja protetiva; o pedido deve ser **indeferido** mediante emissão de Nota Devolutiva, informando ao solicitante a impossibilidade de atender à busca baseada exclusivamente no nome. | H105: Lei 6.015/1973 — Art. 234:p0; Lei 6.015/1973 — Art. 222:p0; Código de Normas CGJ-CE — Art. 1416:p287; Código de Normas CGJ-CE — Art. 1311:p267; Código de Normas CGJ-CE — Art. 1128:p229 | I105: 2.37 | J105: 1483 | K105: 775 | L105: =IF(COUNT(J105:K105)=2,(J105*Parametros!$B$3+K105*Parametros!$B$4)/1000000*Parametros!$B$5,"") | R105: =IF(COUNT(M105:Q105)=5,SUM(M105:Q105),"") | T105: 2 | U105: 1 | V105: =IF(AND(ISNUMBER(T105),T105>0),U105/T105,"") | W105: Art. 7 (LGPD (Lei 13.709/2018)) → NAO_RECUPERADA [recuperado em: nenhum trecho recuperado] | X105: RESPONDIDA
A106: 5 | B106: RAG Fase 3 | C106: =INDEX(Perguntas!$B$2:$B$26,MATCH(A106,Perguntas!$A$2:$A$26,0)) | D106: =INDEX(Perguntas!$C$2:$C$26,MATCH(A106,Perguntas!$A$2:$A$26,0)) | E106: 2026-10-13 | F106: groq/openai/gpt-oss-20b k=5 (26168ce) | G106: **Procedimento para busca de bens do devedor por CPF** 1. **Requerimento ao Oficial do Registro de Imóveis** O credor deve protocolar um requerimento ao Oficial do Registro de Imóveis, contendo: - CPF e nome do devedor (e, se for casado, do cônjuge) – **Art. 1659, inciso I**; - Endereço residencial atual e anterior, se houver – **Art. 1659, inciso II**; - Endereço comercial, se houver – **Art. 1659, inciso III**; - Qualificação completa das partes (nome, domicílio, nacionalidade, estado civil, regime de bens, profissão, CPF ou documento de identidade) – **Art. 1.103 do Provimento 15/2026/CGJCE**. 2. **Busca de bens** O Oficial, com base no CPF informado, realiza a busca no Registro de Imóveis e emite um **certificado de busca de bens** (lista de imóveis registrados em nome do CPF). 3. **Intimação do devedor (se necessário)** Caso o devedor não seja localizado nos endereços indicados, o Oficial procede à intimação conforme **Art. 1666** (intimação por hora certa, com possibilidade de intimar pessoas próximas ou funcionários de portaria, se aplicável). 4. **Entrega do resultado** O certificado de busca, acompanhado de eventuais comprovantes de intimação, é entregue ao credor, permitindo-lhe prosseguir com as medidas de cobrança ou execução. > **Resumo**: O credor solicita a busca de bens do devedor por CPF, seguindo os requisitos de Art. 1659 e Art. 1.103, e o Oficial realiza a busca e, se necessário, a intimação conforme Art. 1666. | H106: Código de Normas CGJ-CE — Art. 1666:p342; Código de Normas CGJ-CE — Art. 1659:p339; Código de Normas CGJ-CE — Art. 1621:p330; Provimento 15/2026/CGJCE — Art. 1:p2 | I106: 2.04 | J106: 2169 | K106: 1217 | L106: =IF(COUNT(J106:K106)=2,(J106*Parametros!$B$3+K106*Parametros!$B$4)/1000000*Parametros!$B$5,"") | R106: =IF(COUNT(M106:Q106)=5,SUM(M106:Q106),"") | T106: 4 | U106: 2 | V106: =IF(AND(ISNUMBER(T106),T106>0),U106/T106,"") | W106: Art. 1103 (Provimento 15/2026/CGJCE) → NAO_RECUPERADA [recuperado em: nenhum trecho recuperado]; Art. 1103 (norma não informada) → NAO_RECUPERADA [recuperado em: nenhum trecho recuperado] | X106: RESPONDIDA
A107: 6 | B107: RAG Fase 3 | C107: =INDEX(Perguntas!$B$2:$B$26,MATCH(A107,Perguntas!$A$2:$A$26,0)) | D107: =INDEX(Perguntas!$C$2:$C$26,MATCH(A107,Perguntas!$A$2:$A$26,0)) | E107: 2026-10-13 | F107: groq/openai/gpt-oss-20b k=5 (26168ce) | G107: Não encontrado no corpus. | H107: Código de Normas CGJ-CE — Art. 1394:p282; Código de Normas CGJ-CE — Art. 1456:p297; Código de Normas CGJ-CE — Art. 1386:p281; Provimento CNJ 149/2023 — Art. 426:p269; Código de Normas CGJ-CE — Art. 1364:p277 | I107: 1.83 | J107: 1783 | K107: 671 | L107: =IF(COUNT(J107:K107)=2,(J107*Parametros!$B$3+K107*Parametros!$B$4)/1000000*Parametros!$B$5,"") | R107: =IF(COUNT(M107:Q107)=5,SUM(M107:Q107),"") | T107: 0 | U107: 0 | V107: =IF(AND(ISNUMBER(T107),T107>0),U107/T107,"") | X107: NAO_ENCONTRADO
A108: 7 | B108: RAG Fase 3 | C108: =INDEX(Perguntas!$B$2:$B$26,MATCH(A108,Perguntas!$A$2:$A$26,0)) | D108: =INDEX(Perguntas!$C$2:$C$26,MATCH(A108,Perguntas!$A$2:$A$26,0)) | E108: 2026-10-13 | F108: groq/openai/gpt-oss-20b k=5 (26168ce) | G108: Não encontrado no corpus. | H108: Lei 6.015/1973 — Art. 279:p0; Lei 6.015/1973 — Art. 276:p0; Código de Normas CGJ-CE — Art. 1333:p271; Lei 6.015/1973 — Art. 292:p0; Código de Normas CGJ-CE — Art. 1412:p286 | I108: 1.03 | J108: 1175 | K108: 571 | L108: =IF(COUNT(J108:K108)=2,(J108*Parametros!$B$3+K108*Parametros!$B$4)/1000000*Parametros!$B$5,"") | R108: =IF(COUNT(M108:Q108)=5,SUM(M108:Q108),"") | T108: 0 | U108: 0 | V108: =IF(AND(ISNUMBER(T108),T108>0),U108/T108,"") | X108: NAO_ENCONTRADO
A109: 8 | B109: RAG Fase 3 | C109: =INDEX(Perguntas!$B$2:$B$26,MATCH(A109,Perguntas!$A$2:$A$26,0)) | D109: =INDEX(Perguntas!$C$2:$C$26,MATCH(A109,Perguntas!$A$2:$A$26,0)) | E109: 2026-10-13 | F109: groq/openai/gpt-oss-120b k=5 (26168ce) | G109: **Resposta:** Forneça a lista, porém o fornecimento deve ser realizado **integralmente, porém condicionado ao cumprimento das normas de proteção de dados** (LGPD) e ao uso da interface eletrônica prevista no Provimento CNJ 149/2023. **Fundamentação normativa** 1. **Provimento CNJ 149/2023 – Art. 184‑A, §§ 4º, 5º e 6º** > “§ 4º O CNB/CF e o ONR disponibilizarão acesso aos municípios, para obtenção das informações, mediante convênio padronizado, para fins de os destinatários das informações atenderem ao disposto nas regras de proteção de dados e de sigilo fiscal.” > “§ 5º O acesso pode ocorrer mediante plataforma que permita aos municípios obterem, em um mesmo ambiente eletrônico, as informações.” > “§ 6º Caberão ao CNB/CF e ao ONR a elaboração de manual técnico em que serão estabelecidos o formato dos dados e o padrão dos programas de interface eletrônica (API), a serem utilizados no intercâmbio de dados estruturados entre as serventias extrajudiciais e as municipalidades.” Esses dispositivos autorizam o compartilhamento de dados cadastrais (matrícula, proprietário, CPF) com a municipalidade, **desde que obedecidos**: * o **convênio padronizado** entre a serventia e o município; * o **manual técnico** que define o **formato** (arquivo estruturado – ex.: JSON ou XML) e a **API** a ser utilizada; * as **regras de proteção de dados e sigilo fiscal** previstas na LGPD (Lei 13.709/2018). 2. **LGPD (Lei 13.709/2018)** – embora não haja artigo específico citado no corpus, a própria norma impõe que o tratamento de dados pessoais (nome, CPF) seja realizado em conformidade com os princípios de finalidade, adequação, necessidade e segurança, o que reforça a necessidade de uso da interface eletrônica prevista no provimento acima. **Procedimento operacional** | Etapa | Descrição | Base legal | |------|-----------|------------| | **a) Convênio** | Verificar a existência de convênio padronizado entre o cartório e a prefeitura. | Prov. CNJ 149/2023, art. 184‑A, § 4º | | **b) Manual técnico** | Utilizar o manual técnico elaborado pelo CNB/CF e ONR para gerar o arquivo no formato definido (ex.: JSON / XML) e disponibilizá‑lo via API. | Prov. CNJ 149/2023, art. 184‑A, § 6º | | **c) Proteção de dados** | Garantir que o acesso seja autenticado, que o arquivo contenha apenas os campos necessários (matrícula, nome, CPF) e que seja armazenado e transmitido com criptografia, em observância à LGPD. | LGPD – princípios de necessidade e segurança | | **d) Registro da transmissão** | Arquivar a solicitação da prefeitura, o comprovante de envio da API e o relatório de conformidade LGPD. | Não há dispositivo específico no corpus; prática recomendada de controle interno. | **Conclusão** - O ato de fornecer a lista de imóveis com proprietários e CPFs à prefeitura **deve ser praticado integralmente**, porém **condicionado** ao cumprimento das exigências de **proteção de dados** e ao **uso da interface eletrônica (API) prevista** nos §§ 4º, 5º e 6º do **Art. 184‑A do Provimento CNJ 149/2023**. - Não há necessidade de “tarjamento protetivo” (cobertura de dados) quando o compartilhamento ocorre via canal oficial (API) e dentro do escopo do convênio, pois a proteção será assegurada pelos mecanismos de segurança da própria plataforma. - Caso não exista convênio ou a prefeitura exija o envio em formato físico (planilha impressa), o fornecimento **deve ser indeferido via Nota Devolutiva**, pois violaria a exigência de uso da interface eletrônica e de observância da LGPD. **Portanto:** forneça a lista **integralmente**, mediante a API padronizada estabelecida pelo CNB/CF e ONR, observando integralmente as regras de proteção de dados da LGPD. | H109: Código de Normas CGJ-CE — Art. 1416:p287; Código de Normas CGJ-CE — Art. 1394:p282; Código de Normas CGJ-CE — Art. 1498:p307; Provimento CNJ 149/2023 — Art. 184-A:p88 | I109: 8.03 | J109: 2097 | K109: 1609 | L109: =IF(COUNT(J109:K109)=2,(J109*Parametros!$B$3+K109*Parametros!$B$4)/1000000*Parametros!$B$5,"") | R109: =IF(COUNT(M109:Q109)=5,SUM(M109:Q109),"") | T109: 1 | U109: 1 | V109: =IF(AND(ISNUMBER(T109),T109>0),U109/T109,"") | X109: RESPONDIDA
A110: 9 | B110: RAG Fase 3 | C110: =INDEX(Perguntas!$B$2:$B$26,MATCH(A110,Perguntas!$A$2:$A$26,0)) | D110: =INDEX(Perguntas!$C$2:$C$26,MATCH(A110,Perguntas!$A$2:$A$26,0)) | E110: 2026-10-13 | F110: groq/openai/gpt-oss-20b k=5 (26168ce) | G110: **Resposta Jurídica e Operacional** O ato de fornecer os dados solicitados pela polícia, sem que exista ordem judicial que autorize tal tratamento, deve ser **indeferido por meio de Nota Devolutiva**. **Fundamentação:** - **Código de Normas CGJ‑CE, Art. 1128, § 4º**: “Caracterizada tentativa de tratamento de dados em desacordo com as finalidades do Registro de Imóveis e com os princípios da Lei Geral de Proteção de Dados Pessoais, poderá o Oficial recusar o fornecimento em nota fundamentada, do que caberá revisão pelo juízo competente.” Como não há ordem judicial que autorize a divulgação dos dados pessoais do proprietário, a solicitação viola os princípios da LGPD e as finalidades do Registro de Imóveis. Portanto, o oficial deve recusar o pedido, emitindo uma Nota Devolutiva fundamentada no Art. 1128, § 4º. | H110: Código de Normas CGJ-CE — Art. 1464:p299; Lei 6.015/1973 — Art. 283:p0; Provimento CNJ 149/2023 — Art. 320-AE:p205; Código de Normas CGJ-CE — Art. 1128:p229; Provimento CNJ 149/2023 — Art. 320-AK:p206 | I110: 1.73 | J110: 1605 | K110: 905 | L110: =IF(COUNT(J110:K110)=2,(J110*Parametros!$B$3+K110*Parametros!$B$4)/1000000*Parametros!$B$5,"") | R110: =IF(COUNT(M110:Q110)=5,SUM(M110:Q110),"") | T110: 2 | U110: 2 | V110: =IF(AND(ISNUMBER(T110),T110>0),U110/T110,"") | X110: RESPONDIDA
A111: 10 | B111: RAG Fase 3 | C111: =INDEX(Perguntas!$B$2:$B$26,MATCH(A111,Perguntas!$A$2:$A$26,0)) | D111: =INDEX(Perguntas!$C$2:$C$26,MATCH(A111,Perguntas!$A$2:$A$26,0)) | E111: 2026-10-13 | F111: groq/openai/gpt-oss-20b k=5 (26168ce) | G111: Não encontrado no corpus. | H111: Código de Normas CGJ-CE — Art. 1367:p277; Código de Normas CGJ-CE — Art. 1141:p232; Código de Normas CGJ-CE — Art. 1128:p229; Código de Normas CGJ-CE — Art. 1127:p229; Lei 6.015/1973 — Art. 176-O:p0 | I111: 11.23 | J111: 1399 | K111: 651 | L111: =IF(COUNT(J111:K111)=2,(J111*Parametros!$B$3+K111*Parametros!$B$4)/1000000*Parametros!$B$5,"") | R111: =IF(COUNT(M111:Q111)=5,SUM(M111:Q111),"") | T111: 0 | U111: 0 | V111: =IF(AND(ISNUMBER(T111),T111>0),U111/T111,"") | X111: NAO_ENCONTRADO
A112: 11 | B112: RAG Fase 3 | C112: =INDEX(Perguntas!$B$2:$B$26,MATCH(A112,Perguntas!$A$2:$A$26,0)) | D112: =INDEX(Perguntas!$C$2:$C$26,MATCH(A112,Perguntas!$A$2:$A$26,0)) | E112: 2026-10-13 | F112: groq/openai/gpt-oss-120b k=5 (26168ce) | G112: Não encontrado no corpus. | H112: LAI (Lei 12.527/2011) — Art. 8:p0; LAI (Lei 12.527/2011) — Art. 14:p0; LAI (Lei 12.527/2011) — Art. 11:p0; LAI (Lei 12.527/2011) — Art. 41:p0 | I112: 1.38 | J112: 1578 | K112: 396 | L112: =IF(COUNT(J112:K112)=2,(J112*Parametros!$B$3+K112*Parametros!$B$4)/1000000*Parametros!$B$5,"") | R112: =IF(COUNT(M112:Q112)=5,SUM(M112:Q112),"") | T112: 0 | U112: 0 | V112: =IF(AND(ISNUMBER(T112),T112>0),U112/T112,"") | X112: NAO_ENCONTRADO
A113: 12 | B113: RAG Fase 3 | C113: =INDEX(Perguntas!$B$2:$B$26,MATCH(A113,Perguntas!$A$2:$A$26,0)) | D113: =INDEX(Perguntas!$C$2:$C$26,MATCH(A113,Perguntas!$A$2:$A$26,0)) | E113: 2026-10-13 | F113: groq/openai/gpt-oss-20b k=5 (26168ce) | G113: **Resposta Jurídica e Operacional** Sim, é dever responder ao pedido de acesso à informação sobre os emolumentos arrecadados pela serventia. **Fundamentação normativa** - **LAI – Art. 10** - § 1º: “Qualquer interessado poderá apresentar pedido de acesso a informações … devendo o pedido conter a identificação do requerente e a especificação da informação requerida.” - § 2º: “Os órgãos e entidades do poder público devem viabilizar alternativa de encaminhamento de pedidos de acesso por meio de seus sítios oficiais na internet.” - § 3º: “São vedadas quaisquer exigências relativas aos motivos determinantes da solicitação de informações de interesse público.” - **LAI – Art. 14** - “É direito do requerente obter o inteiro teor de decisão de negativa de acesso, por certidão ou cópia.” Portanto, a serventia deve atender ao pedido, fornecendo a informação solicitada ou, se houver motivo legítimo para negar, deve apresentar a decisão de negativa com o inteiro teor, conforme Art. 14. **Conclusão** O ato registral de resposta ao pedido via LAI deve ser praticado integralmente, obedecendo aos dispositivos citados. | H113: LAI (Lei 12.527/2011) — Art. 14:p0; Provimento CNJ 149/2023 — Art. 228-U:p134; LAI (Lei 12.527/2011) — Art. 10:p0; LAI (Lei 12.527/2011) — Art. 13:p0; Provimento CNJ 149/2023 — Art. 71-J:p35 | I113: 11.78 | J113: 1458 | K113: 1675 | L113: =IF(COUNT(J113:K113)=2,(J113*Parametros!$B$3+K113*Parametros!$B$4)/1000000*Parametros!$B$5,"") | R113: =IF(COUNT(M113:Q113)=5,SUM(M113:Q113),"") | T113: 3 | U113: 3 | V113: =IF(AND(ISNUMBER(T113),T113>0),U113/T113,"") | X113: RESPONDIDA
A114: 13 | B114: RAG Fase 3 | C114: =INDEX(Perguntas!$B$2:$B$26,MATCH(A114,Perguntas!$A$2:$A$26,0)) | D114: =INDEX(Perguntas!$C$2:$C$26,MATCH(A114,Perguntas!$A$2:$A$26,0)) | E114: 2026-10-13 | F114: groq/openai/gpt-oss-20b k=5 (26168ce) | G114: **Resposta** A certidão não pode ser emitida sem incluir a averbação de interdição/curatela que consta na matrícula. **Dispositivo legal** - Lei 6.015/1973, Art. 19, § 11: “No âmbito do registro de imóveis, a certidão de inteiro teor da matrícula conterá a reprodução de todo seu conteúdo e será suficiente para fins de comprovação de propriedade, direitos, ônus reais e restrições sobre o imóvel, independentemente de certificação específica pelo oficial.” - Lei 6.015/1973, Art. 230: “Se na certidão constar ônus, o oficial fará a matrícula, e, logo em seguida ao registro, averbará a existência do ônus, sua natureza e valor, certificando o fato no título que devolverá à parte.” **Conclusão** O ato deve ser **indefere via Nota Devolutiva**. A certidão de inteiro teor deve reproduzir integralmente a averbação de interdição/curatela; omiti-la violaria o disposto nos dispositivos citados. | H114: Código de Normas CGJ-CE — Art. 1131:p229; Lei 6.015/1973 — Art. 19:p0; Lei 6.015/1973 — Art. 230:p0; Código de Normas CGJ-CE — Art. 1416:p287; Provimento CNJ 149/2023 — Art. 201:p94 | I114: 25.55 | J114: 1771 | K114: 717 | L114: =IF(COUNT(J114:K114)=2,(J114*Parametros!$B$3+K114*Parametros!$B$4)/1000000*Parametros!$B$5,"") | R114: =IF(COUNT(M114:Q114)=5,SUM(M114:Q114),"") | T114: 2 | U114: 2 | V114: =IF(AND(ISNUMBER(T114),T114>0),U114/T114,"") | X114: RESPONDIDA
...

Sheet Parametros
A1: Parâmetro | B1: Valor | D1: Fonte / observação
A2: Modelo do RAG | B2: Groq openai/gpt-oss-20b / 120b | D2: CHEAP/PREMIUM_MODEL do .env; o script registra o modelo real em 'Versão / plano'
A3: Preço entrada (US$ / 1M tokens) | B3: 0.15 | D3: Premissa: preço do gpt-oss-120b na Groq (teto; o 20b é mais barato). Conferir em groq.com/pricing
A4: Preço saída (US$ / 1M tokens) | B4: 0.6 | D4: Premissa: preço do gpt-oss-120b na Groq (teto; o 20b é mais barato). Conferir em groq.com/pricing
A5: Câmbio (R$ / US$) | B5: 5.5 | D5: Premissa: atualizar com a cotação do dia da coleta
A8: Custo dos concorrentes
A9: Ferramenta | B9: Assinatura mensal (R$) | C9: Consultas / mês estimadas | D9: Custo por consulta (R$)
A10: Jus IA | D10: =IF(AND(ISNUMBER(B10),ISNUMBER(C10),C10>0),B10/C10,"")
A11: Jurídico AI | D11: =IF(AND(ISNUMBER(B11),ISNUMBER(C11),C11>0),B11/C11,"")
A12: LLM genérico | D12: =IF(AND(ISNUMBER(B12),ISNUMBER(C12),C12>0),B12/C12,"")
A14: O custo por consulta dos RAGs vem dos tokens medidos (aba Respostas).

Sheet Resumo
A1: Resumo do benchmark
A3: Ferramenta | B3: Avaliadas | C3: Nota média (0-10) | D3: Veredito | E3: Fundamentação | F3: Norma CE | G3: Acionável | H3: Sem alucinação | I3: % notas ≥ 8 | J3: Latência média (s) | K3: Custo / consulta (R$) | L3: Taxa verificável (citações) | M3: Respondidas | N3: Não encontrado | O3: Resposta vazia
A4: Jus IA | B4: =COUNTIFS(Respostas!$B$2:$B$126,$A4,Respostas!$R$2:$R$126,">=0") | C4: =IF(B4=0,"",AVERAGEIFS(Respostas!$R$2:$R$126,Respostas!$B$2:$B$126,$A4)) | D4: =IF(B4=0,"",AVERAGEIFS(Respostas!$M$2:$M$126,Respostas!$B$2:$B$126,$A4,Respostas!$R$2:$R$126,">=0")) | E4: =IF(B4=0,"",AVERAGEIFS(Respostas!$N$2:$N$126,Respostas!$B$2:$B$126,$A4,Respostas!$R$2:$R$126,">=0")) | F4: =IF(B4=0,"",AVERAGEIFS(Respostas!$O$2:$O$126,Respostas!$B$2:$B$126,$A4,Respostas!$R$2:$R$126,">=0")) | G4: =IF(B4=0,"",AVERAGEIFS(Respostas!$P$2:$P$126,Respostas!$B$2:$B$126,$A4,Respostas!$R$2:$R$126,">=0")) | H4: =IF(B4=0,"",AVERAGEIFS(Respostas!$Q$2:$Q$126,Respostas!$B$2:$B$126,$A4,Respostas!$R$2:$R$126,">=0")) | I4: =IF(B4=0,"",COUNTIFS(Respostas!$B$2:$B$126,$A4,Respostas!$R$2:$R$126,">=8")/B4) | J4: =IF(COUNTIFS(Respostas!$B$2:$B$126,$A4,Respostas!$I$2:$I$126,">=0")=0,"",AVERAGEIFS(Respostas!$I$2:$I$126,Respostas!$B$2:$B$126,$A4)) | K4: =IF(ISNUMBER(Parametros!$D$10),Parametros!$D$10,"") | L4: =IF(SUMIFS(Respostas!$T$2:$T$126,Respostas!$B$2:$B$126,$A4)=0,"",SUMIFS(Respostas!$U$2:$U$126,Respostas!$B$2:$B$126,$A4)/SUMIFS(Respostas!$T$2:$T$126,Respostas!$B$2:$B$126,$A4)) | M4: =COUNTIFS(Respostas!$B$2:$B$126,$A4,Respostas!$X$2:$X$126,"RESPONDIDA") | N4: =COUNTIFS(Respostas!$B$2:$B$126,$A4,Respostas!$X$2:$X$126,"NAO_ENCONTRADO") | O4: =COUNTIFS(Respostas!$B$2:$B$126,$A4,Respostas!$X$2:$X$126,"RESPOSTA_VAZIA")
A5: Jurídico AI | B5: =COUNTIFS(Respostas!$B$2:$B$126,$A5,Respostas!$R$2:$R$126,">=0") | C5: =IF(B5=0,"",AVERAGEIFS(Respostas!$R$2:$R$126,Respostas!$B$2:$B$126,$A5)) | D5: =IF(B5=0,"",AVERAGEIFS(Respostas!$M$2:$M$126,Respostas!$B$2:$B$126,$A5,Respostas!$R$2:$R$126,">=0")) | E5: =IF(B5=0,"",AVERAGEIFS(Respostas!$N$2:$N$126,Respostas!$B$2:$B$126,$A5,Respostas!$R$2:$R$126,">=0")) | F5: =IF(B5=0,"",AVERAGEIFS(Respostas!$O$2:$O$126,Respostas!$B$2:$B$126,$A5,Respostas!$R$2:$R$126,">=0")) | G5: =IF(B5=0,"",AVERAGEIFS(Respostas!$P$2:$P$126,Respostas!$B$2:$B$126,$A5,Respostas!$R$2:$R$126,">=0")) | H5: =IF(B5=0,"",AVERAGEIFS(Respostas!$Q$2:$Q$126,Respostas!$B$2:$B$126,$A5,Respostas!$R$2:$R$126,">=0")) | I5: =IF(B5=0,"",COUNTIFS(Respostas!$B$2:$B$126,$A5,Respostas!$R$2:$R$126,">=8")/B5) | J5: =IF(COUNTIFS(Respostas!$B$2:$B$126,$A5,Respostas!$I$2:$I$126,">=0")=0,"",AVERAGEIFS(Respostas!$I$2:$I$126,Respostas!$B$2:$B$126,$A5)) | K5: =IF(ISNUMBER(Parametros!$D$11),Parametros!$D$11,"") | L5: =IF(SUMIFS(Respostas!$T$2:$T$126,Respostas!$B$2:$B$126,$A5)=0,"",SUMIFS(Respostas!$U$2:$U$126,Respostas!$B$2:$B$126,$A5)/SUMIFS(Respostas!$T$2:$T$126,Respostas!$B$2:$B$126,$A5)) | M5: =COUNTIFS(Respostas!$B$2:$B$126,$A5,Respostas!$X$2:$X$126,"RESPONDIDA") | N5: =COUNTIFS(Respostas!$B$2:$B$126,$A5,Respostas!$X$2:$X$126,"NAO_ENCONTRADO") | O5: =COUNTIFS(Respostas!$B$2:$B$126,$A5,Respostas!$X$2:$X$126,"RESPOSTA_VAZIA")
A6: LLM genérico | B6: =COUNTIFS(Respostas!$B$2:$B$126,$A6,Respostas!$R$2:$R$126,">=0") | C6: =IF(B6=0,"",AVERAGEIFS(Respostas!$R$2:$R$126,Respostas!$B$2:$B$126,$A6)) | D6: =IF(B6=0,"",AVERAGEIFS(Respostas!$M$2:$M$126,Respostas!$B$2:$B$126,$A6,Respostas!$R$2:$R$126,">=0")) | E6: =IF(B6=0,"",AVERAGEIFS(Respostas!$N$2:$N$126,Respostas!$B$2:$B$126,$A6,Respostas!$R$2:$R$126,">=0")) | F6: =IF(B6=0,"",AVERAGEIFS(Respostas!$O$2:$O$126,Respostas!$B$2:$B$126,$A6,Respostas!$R$2:$R$126,">=0")) | G6: =IF(B6=0,"",AVERAGEIFS(Respostas!$P$2:$P$126,Respostas!$B$2:$B$126,$A6,Respostas!$R$2:$R$126,">=0")) | H6: =IF(B6=0,"",AVERAGEIFS(Respostas!$Q$2:$Q$126,Respostas!$B$2:$B$126,$A6,Respostas!$R$2:$R$126,">=0")) | I6: =IF(B6=0,"",COUNTIFS(Respostas!$B$2:$B$126,$A6,Respostas!$R$2:$R$126,">=8")/B6) | J6: =IF(COUNTIFS(Respostas!$B$2:$B$126,$A6,Respostas!$I$2:$I$126,">=0")=0,"",AVERAGEIFS(Respostas!$I$2:$I$126,Respostas!$B$2:$B$126,$A6)) | K6: =IF(ISNUMBER(Parametros!$D$12),Parametros!$D$12,"") | L6: =IF(SUMIFS(Respostas!$T$2:$T$126,Respostas!$B$2:$B$126,$A6)=0,"",SUMIFS(Respostas!$U$2:$U$126,Respostas!$B$2:$B$126,$A6)/SUMIFS(Respostas!$T$2:$T$126,Respostas!$B$2:$B$126,$A6)) | M6: =COUNTIFS(Respostas!$B$2:$B$126,$A6,Respostas!$X$2:$X$126,"RESPONDIDA") | N6: =COUNTIFS(Respostas!$B$2:$B$126,$A6,Respostas!$X$2:$X$126,"NAO_ENCONTRADO") | O6: =COUNTIFS(Respostas!$B$2:$B$126,$A6,Respostas!$X$2:$X$126,"RESPOSTA_VAZIA")
A7: RAG atual | B7: =COUNTIFS(Respostas!$B$2:$B$126,$A7,Respostas!$R$2:$R$126,">=0") | C7: =IF(B7=0,"",AVERAGEIFS(Respostas!$R$2:$R$126,Respostas!$B$2:$B$126,$A7)) | D7: =IF(B7=0,"",AVERAGEIFS(Respostas!$M$2:$M$126,Respostas!$B$2:$B$126,$A7,Respostas!$R$2:$R$126,">=0")) | E7: =IF(B7=0,"",AVERAGEIFS(Respostas!$N$2:$N$126,Respostas!$B$2:$B$126,$A7,Respostas!$R$2:$R$126,">=0")) | F7: =IF(B7=0,"",AVERAGEIFS(Respostas!$O$2:$O$126,Respostas!$B$2:$B$126,$A7,Respostas!$R$2:$R$126,">=0")) | G7: =IF(B7=0,"",AVERAGEIFS(Respostas!$P$2:$P$126,Respostas!$B$2:$B$126,$A7,Respostas!$R$2:$R$126,">=0")) | H7: =IF(B7=0,"",AVERAGEIFS(Respostas!$Q$2:$Q$126,Respostas!$B$2:$B$126,$A7,Respostas!$R$2:$R$126,">=0")) | I7: =IF(B7=0,"",COUNTIFS(Respostas!$B$2:$B$126,$A7,Respostas!$R$2:$R$126,">=8")/B7) | J7: =IF(COUNTIFS(Respostas!$B$2:$B$126,$A7,Respostas!$I$2:$I$126,">=0")=0,"",AVERAGEIFS(Respostas!$I$2:$I$126,Respostas!$B$2:$B$126,$A7)) | K7: =IF(COUNTIFS(Respostas!$B$2:$B$126,$A7,Respostas!$L$2:$L$126,">=0")=0,"",AVERAGEIFS(Respostas!$L$2:$L$126,Respostas!$B$2:$B$126,$A7)) | L7: =IF(SUMIFS(Respostas!$T$2:$T$126,Respostas!$B$2:$B$126,$A7)=0,"",SUMIFS(Respostas!$U$2:$U$126,Respostas!$B$2:$B$126,$A7)/SUMIFS(Respostas!$T$2:$T$126,Respostas!$B$2:$B$126,$A7)) | M7: =COUNTIFS(Respostas!$B$2:$B$126,$A7,Respostas!$X$2:$X$126,"RESPONDIDA") | N7: =COUNTIFS(Respostas!$B$2:$B$126,$A7,Respostas!$X$2:$X$126,"NAO_ENCONTRADO") | O7: =COUNTIFS(Respostas!$B$2:$B$126,$A7,Respostas!$X$2:$X$126,"RESPOSTA_VAZIA")
A8: RAG Fase 3 | B8: =COUNTIFS(Respostas!$B$2:$B$126,$A8,Respostas!$R$2:$R$126,">=0") | C8: =IF(B8=0,"",AVERAGEIFS(Respostas!$R$2:$R$126,Respostas!$B$2:$B$126,$A8)) | D8: =IF(B8=0,"",AVERAGEIFS(Respostas!$M$2:$M$126,Respostas!$B$2:$B$126,$A8,Respostas!$R$2:$R$126,">=0")) | E8: =IF(B8=0,"",AVERAGEIFS(Respostas!$N$2:$N$126,Respostas!$B$2:$B$126,$A8,Respostas!$R$2:$R$126,">=0")) | F8: =IF(B8=0,"",AVERAGEIFS(Respostas!$O$2:$O$126,Respostas!$B$2:$B$126,$A8,Respostas!$R$2:$R$126,">=0")) | G8: =IF(B8=0,"",AVERAGEIFS(Respostas!$P$2:$P$126,Respostas!$B$2:$B$126,$A8,Respostas!$R$2:$R$126,">=0")) | H8: =IF(B8=0,"",AVERAGEIFS(Respostas!$Q$2:$Q$126,Respostas!$B$2:$B$126,$A8,Respostas!$R$2:$R$126,">=0")) | I8: =IF(B8=0,"",COUNTIFS(Respostas!$B$2:$B$126,$A8,Respostas!$R$2:$R$126,">=8")/B8) | J8: =IF(COUNTIFS(Respostas!$B$2:$B$126,$A8,Respostas!$I$2:$I$126,">=0")=0,"",AVERAGEIFS(Respostas!$I$2:$I$126,Respostas!$B$2:$B$126,$A8)) | K8: =IF(COUNTIFS(Respostas!$B$2:$B$126,$A8,Respostas!$L$2:$L$126,">=0")=0,"",AVERAGEIFS(Respostas!$L$2:$L$126,Respostas!$B$2:$B$126,$A8)) | L8: =IF(SUMIFS(Respostas!$T$2:$T$126,Respostas!$B$2:$B$126,$A8)=0,"",SUMIFS(Respostas!$U$2:$U$126,Respostas!$B$2:$B$126,$A8)/SUMIFS(Respostas!$T$2:$T$126,Respostas!$B$2:$B$126,$A8)) | M8: =COUNTIFS(Respostas!$B$2:$B$126,$A8,Respostas!$X$2:$X$126,"RESPONDIDA") | N8: =COUNTIFS(Respostas!$B$2:$B$126,$A8,Respostas!$X$2:$X$126,"NAO_ENCONTRADO") | O8: =COUNTIFS(Respostas!$B$2:$B$126,$A8,Respostas!$X$2:$X$126,"RESPOSTA_VAZIA")
A10: Gate 1: sinal do benchmark
A11: Melhor concorrente | B11: =IF(COUNT(C4,C5,C6)=0,"",MAX(C4,C5,C6))
A12: Sinal | B12: =IF(B11="","Aguardando coleta",IF(B11>=8,"Concorrentes fortes: só seguir se as entrevistas mostrarem dor mensurável",IF(B11<6,"Gap confirmado: seguir com H1 + H3","Zona cinza: focar em H3 + H4 (fluxo + custo)")))
A13: Regras em docs/fase3/03_plano_validacao.md. O Gate combina este sinal com as entrevistas.
A15: Nota média por categoria
A16: Categoria | B16: Jus IA | C16: Jurídico AI | D16: LLM genérico | E16: RAG atual | F16: RAG Fase 3
A17: Certidão | B17: =IF(COUNTIFS(Respostas!$B$2:$B$126,B$16,Respostas!$C$2:$C$126,$A17,Respostas!$R$2:$R$126,">=0")=0,"",AVERAGEIFS(Respostas!$R$2:$R$126,Respostas!$B$2:$B$126,B$16,Respostas!$C$2:$C$126,$A17)) | C17: =IF(COUNTIFS(Respostas!$B$2:$B$126,C$16,Respostas!$C$2:$C$126,$A17,Respostas!$R$2:$R$126,">=0")=0,"",AVERAGEIFS(Respostas!$R$2:$R$126,Respostas!$B$2:$B$126,C$16,Respostas!$C$2:$C$126,$A17)) | D17: =IF(COUNTIFS(Respostas!$B$2:$B$126,D$16,Respostas!$C$2:$C$126,$A17,Respostas!$R$2:$R$126,">=0")=0,"",AVERAGEIFS(Respostas!$R$2:$R$126,Respostas!$B$2:$B$126,D$16,Respostas!$C$2:$C$126,$A17)) | E17: =IF(COUNTIFS(Respostas!$B$2:$B$126,E$16,Respostas!$C$2:$C$126,$A17,Respostas!$R$2:$R$126,">=0")=0,"",AVERAGEIFS(Respostas!$R$2:$R$126,Respostas!$B$2:$B$126,E$16,Respostas!$C$2:$C$126,$A17)) | F17: =IF(COUNTIFS(Respostas!$B$2:$B$126,F$16,Respostas!$C$2:$C$126,$A17,Respostas!$R$2:$R$126,">=0")=0,"",AVERAGEIFS(Respostas!$R$2:$R$126,Respostas!$B$2:$B$126,F$16,Respostas!$C$2:$C$126,$A17))
A18: Busca | B18: =IF(COUNTIFS(Respostas!$B$2:$B$126,B$16,Respostas!$C$2:$C$126,$A18,Respostas!$R$2:$R$126,">=0")=0,"",AVERAGEIFS(Respostas!$R$2:$R$126,Respostas!$B$2:$B$126,B$16,Respostas!$C$2:$C$126,$A18)) | C18: =IF(COUNTIFS(Respostas!$B$2:$B$126,C$16,Respostas!$C$2:$C$126,$A18,Respostas!$R$2:$R$126,">=0")=0,"",AVERAGEIFS(Respostas!$R$2:$R$126,Respostas!$B$2:$B$126,C$16,Respostas!$C$2:$C$126,$A18)) | D18: =IF(COUNTIFS(Respostas!$B$2:$B$126,D$16,Respostas!$C$2:$C$126,$A18,Respostas!$R$2:$R$126,">=0")=0,"",AVERAGEIFS(Respostas!$R$2:$R$126,Respostas!$B$2:$B$126,D$16,Respostas!$C$2:$C$126,$A18)) | E18: =IF(COUNTIFS(Respostas!$B$2:$B$126,E$16,Respostas!$C$2:$C$126,$A18,Respostas!$R$2:$R$126,">=0")=0,"",AVERAGEIFS(Respostas!$R$2:$R$126,Respostas!$B$2:$B$126,E$16,Respostas!$C$2:$C$126,$A18)) | F18: =IF(COUNTIFS(Respostas!$B$2:$B$126,F$16,Respostas!$C$2:$C$126,$A18,Respostas!$R$2:$R$126,">=0")=0,"",AVERAGEIFS(Respostas!$R$2:$R$126,Respostas!$B$2:$B$126,F$16,Respostas!$C$2:$C$126,$A18))
A19: Informação verbal | B19: =IF(COUNTIFS(Respostas!$B$2:$B$126,B$16,Respostas!$C$2:$C$126,$A19,Respostas!$R$2:$R$126,">=0")=0,"",AVERAGEIFS(Respostas!$R$2:$R$126,Respostas!$B$2:$B$126,B$16,Respostas!$C$2:$C$126,$A19)) | C19: =IF(COUNTIFS(Respostas!$B$2:$B$126,C$16,Respostas!$C$2:$C$126,$A19,Respostas!$R$2:$R$126,">=0")=0,"",AVERAGEIFS(Respostas!$R$2:$R$126,Respostas!$B$2:$B$126,C$16,Respostas!$C$2:$C$126,$A19)) | D19: =IF(COUNTIFS(Respostas!$B$2:$B$126,D$16,Respostas!$C$2:$C$126,$A19,Respostas!$R$2:$R$126,">=0")=0,"",AVERAGEIFS(Respostas!$R$2:$R$126,Respostas!$B$2:$B$126,D$16,Respostas!$C$2:$C$126,$A19)) | E19: =IF(COUNTIFS(Respostas!$B$2:$B$126,E$16,Respostas!$C$2:$C$126,$A19,Respostas!$R$2:$R$126,">=0")=0,"",AVERAGEIFS(Respostas!$R$2:$R$126,Respostas!$B$2:$B$126,E$16,Respostas!$C$2:$C$126,$A19)) | F19: =IF(COUNTIFS(Respostas!$B$2:$B$126,F$16,Respostas!$C$2:$C$126,$A19,Respostas!$R$2:$R$126,">=0")=0,"",AVERAGEIFS(Respostas!$R$2:$R$126,Respostas!$B$2:$B$126,F$16,Respostas!$C$2:$C$126,$A19))
A20: Poder público | B20: =IF(COUNTIFS(Respostas!$B$2:$B$126,B$16,Respostas!$C$2:$C$126,$A20,Respostas!$R$2:$R$126,">=0")=0,"",AVERAGEIFS(Respostas!$R$2:$R$126,Respostas!$B$2:$B$126,B$16,Respostas!$C$2:$C$126,$A20)) | C20: =IF(COUNTIFS(Respostas!$B$2:$B$126,C$16,Respostas!$C$2:$C$126,$A20,Respostas!$R$2:$R$126,">=0")=0,"",AVERAGEIFS(Respostas!$R$2:$R$126,Respostas!$B$2:$B$126,C$16,Respostas!$C$2:$C$126,$A20)) | D20: =IF(COUNTIFS(Respostas!$B$2:$B$126,D$16,Respostas!$C$2:$C$126,$A20,Respostas!$R$2:$R$126,">=0")=0,"",AVERAGEIFS(Respostas!$R$2:$R$126,Respostas!$B$2:$B$126,D$16,Respostas!$C$2:$C$126,$A20)) | E20: =IF(COUNTIFS(Respostas!$B$2:$B$126,E$16,Respostas!$C$2:$C$126,$A20,Respostas!$R$2:$R$126,">=0")=0,"",AVERAGEIFS(Respostas!$R$2:$R$126,Respostas!$B$2:$B$126,E$16,Respostas!$C$2:$C$126,$A20)) | F20: =IF(COUNTIFS(Respostas!$B$2:$B$126,F$16,Respostas!$C$2:$C$126,$A20,Respostas!$R$2:$R$126,">=0")=0,"",AVERAGEIFS(Respostas!$R$2:$R$126,Respostas!$B$2:$B$126,F$16,Respostas!$C$2:$C$126,$A20))
A21: Transparência | B21: =IF(COUNTIFS(Respostas!$B$2:$B$126,B$16,Respostas!$C$2:$C$126,$A21,Respostas!$R$2:$R$126,">=0")=0,"",AVERAGEIFS(Respostas!$R$2:$R$126,Respostas!$B$2:$B$126,B$16,Respostas!$C$2:$C$126,$A21)) | C21: =IF(COUNTIFS(Respostas!$B$2:$B$126,C$16,Respostas!$C$2:$C$126,$A21,Respostas!$R$2:$R$126,">=0")=0,"",AVERAGEIFS(Respostas!$R$2:$R$126,Respostas!$B$2:$B$126,C$16,Respostas!$C$2:$C$126,$A21)) | D21: =IF(COUNTIFS(Respostas!$B$2:$B$126,D$16,Respostas!$C$2:$C$126,$A21,Respostas!$R$2:$R$126,">=0")=0,"",AVERAGEIFS(Respostas!$R$2:$R$126,Respostas!$B$2:$B$126,D$16,Respostas!$C$2:$C$126,$A21)) | E21: =IF(COUNTIFS(Respostas!$B$2:$B$126,E$16,Respostas!$C$2:$C$126,$A21,Respostas!$R$2:$R$126,">=0")=0,"",AVERAGEIFS(Respostas!$R$2:$R$126,Respostas!$B$2:$B$126,E$16,Respostas!$C$2:$C$126,$A21)) | F21: =IF(COUNTIFS(Respostas!$B$2:$B$126,F$16,Respostas!$C$2:$C$126,$A21,Respostas!$R$2:$R$126,">=0")=0,"",AVERAGEIFS(Respostas!$R$2:$R$126,Respostas!$B$2:$B$126,F$16,Respostas!$C$2:$C$126,$A21))
A22: Dado sensível | B22: =IF(COUNTIFS(Respostas!$B$2:$B$126,B$16,Respostas!$C$2:$C$126,$A22,Respostas!$R$2:$R$126,">=0")=0,"",AVERAGEIFS(Respostas!$R$2:$R$126,Respostas!$B$2:$B$126,B$16,Respostas!$C$2:$C$126,$A22)) | C22: =IF(COUNTIFS(Respostas!$B$2:$B$126,C$16,Respostas!$C$2:$C$126,$A22,Respostas!$R$2:$R$126,">=0")=0,"",AVERAGEIFS(Respostas!$R$2:$R$126,Respostas!$B$2:$B$126,C$16,Respostas!$C$2:$C$126,$A22)) | D22: =IF(COUNTIFS(Respostas!$B$2:$B$126,D$16,Respostas!$C$2:$C$126,$A22,Respostas!$R$2:$R$126,">=0")=0,"",AVERAGEIFS(Respostas!$R$2:$R$126,Respostas!$B$2:$B$126,D$16,Respostas!$C$2:$C$126,$A22)) | E22: =IF(COUNTIFS(Respostas!$B$2:$B$126,E$16,Respostas!$C$2:$C$126,$A22,Respostas!$R$2:$R$126,">=0")=0,"",AVERAGEIFS(Respostas!$R$2:$R$126,Respostas!$B$2:$B$126,E$16,Respostas!$C$2:$C$126,$A22)) | F22: =IF(COUNTIFS(Respostas!$B$2:$B$126,F$16,Respostas!$C$2:$C$126,$A22,Respostas!$R$2:$R$126,">=0")=0,"",AVERAGEIFS(Respostas!$R$2:$R$126,Respostas!$B$2:$B$126,F$16,Respostas!$C$2:$C$126,$A22))
A23: Tratamento | B23: =IF(COUNTIFS(Respostas!$B$2:$B$126,B$16,Respostas!$C$2:$C$126,$A23,Respostas!$R$2:$R$126,">=0")=0,"",AVERAGEIFS(Respostas!$R$2:$R$126,Respostas!$B$2:$B$126,B$16,Respostas!$C$2:$C$126,$A23)) | C23: =IF(COUNTIFS(Respostas!$B$2:$B$126,C$16,Respostas!$C$2:$C$126,$A23,Respostas!$R$2:$R$126,">=0")=0,"",AVERAGEIFS(Respostas!$R$2:$R$126,Respostas!$B$2:$B$126,C$16,Respostas!$C$2:$C$126,$A23)) | D23: =IF(COUNTIFS(Respostas!$B$2:$B$126,D$16,Respostas!$C$2:$C$126,$A23,Respostas!$R$2:$R$126,">=0")=0,"",AVERAGEIFS(Respostas!$R$2:$R$126,Respostas!$B$2:$B$126,D$16,Respostas!$C$2:$C$126,$A23)) | E23: =IF(COUNTIFS(Respostas!$B$2:$B$126,E$16,Respostas!$C$2:$C$126,$A23,Respostas!$R$2:$R$126,">=0")=0,"",AVERAGEIFS(Respostas!$R$2:$R$126,Respostas!$B$2:$B$126,E$16,Respostas!$C$2:$C$126,$A23)) | F23: =IF(COUNTIFS(Respostas!$B$2:$B$126,F$16,Respostas!$C$2:$C$126,$A23,Respostas!$R$2:$R$126,">=0")=0,"",AVERAGEIFS(Respostas!$R$2:$R$126,Respostas!$B$2:$B$126,F$16,Respostas!$C$2:$C$126,$A23))
A24: Compartilhamento | B24: =IF(COUNTIFS(Respostas!$B$2:$B$126,B$16,Respostas!$C$2:$C$126,$A24,Respostas!$R$2:$R$126,">=0")=0,"",AVERAGEIFS(Respostas!$R$2:$R$126,Respostas!$B$2:$B$126,B$16,Respostas!$C$2:$C$126,$A24)) | C24: =IF(COUNTIFS(Respostas!$B$2:$B$126,C$16,Respostas!$C$2:$C$126,$A24,Respostas!$R$2:$R$126,">=0")=0,"",AVERAGEIFS(Respostas!$R$2:$R$126,Respostas!$B$2:$B$126,C$16,Respostas!$C$2:$C$126,$A24)) | D24: =IF(COUNTIFS(Respostas!$B$2:$B$126,D$16,Respostas!$C$2:$C$126,$A24,Respostas!$R$2:$R$126,">=0")=0,"",AVERAGEIFS(Respostas!$R$2:$R$126,Respostas!$B$2:$B$126,D$16,Respostas!$C$2:$C$126,$A24)) | E24: =IF(COUNTIFS(Respostas!$B$2:$B$126,E$16,Respostas!$C$2:$C$126,$A24,Respostas!$R$2:$R$126,">=0")=0,"",AVERAGEIFS(Respostas!$R$2:$R$126,Respostas!$B$2:$B$126,E$16,Respostas!$C$2:$C$126,$A24)) | F24: =IF(COUNTIFS(Respostas!$B$2:$B$126,F$16,Respostas!$C$2:$C$126,$A24,Respostas!$R$2:$R$126,">=0")=0,"",AVERAGEIFS(Respostas!$R$2:$R$126,Respostas!$B$2:$B$126,F$16,Respostas!$C$2:$C$126,$A24))
